# Bug Fix Document: TypeError in `test_process_complete_speech`

## 1. Bug and Symptoms

**Bug:** The test `test_process_complete_speech` fails with a `TypeError`.

**Symptom:** When running `pytest`, the test fails with the following error message, originating from the `asyncio` library itself:

```
TypeError: a coroutine was expected, got <Future finished result=None>
```

This error occurs on the following line within the `PhoneAgent.process_complete_speech` method:
```python
asyncio.create_task(self.speak(filler))
```

## 2. Root Cause Analysis

This bug is caused by an incorrect mocking strategy for asynchronous methods within our test file `dual_agent/tests/test_phone_agent.py`.

The core of the issue lies in the subtle but important difference between two ways of handling asynchronous calls:

1.  **`await an_async_function()`**: The `await` keyword operates on an **awaitable** object. An `asyncio.Future` is a perfect example of an awaitable.
2.  **`asyncio.create_task(an_async_function())`**: The `asyncio.create_task()` function, however, does **not** take an awaitable as an argument. It expects a **coroutine** object. A coroutine is the object you get when you *call* a function defined with `async def`, but *before* you `await` it.

In our current test setup, we have this code:
```python
# In dual_agent/tests/test_phone_agent.py
agent.speak = MagicMock()
agent.speak.return_value = asyncio.Future()
agent.speak.return_value.set_result(None)
```
When the `PhoneAgent` code calls `self.speak(filler)`, our `MagicMock` is executed. It immediately returns its `return_value`, which is a completed `Future` object. The failing line effectively becomes `asyncio.create_task(<Future object>)`, which is incorrect.

### Consistency Check
As you pointed out, another method was mocked using the same problematic pattern:
```python
agent.send_message_to_computer = MagicMock()
agent.send_message_to_computer.return_value = asyncio.Future()
agent.send_message_to_computer.return_value.set_result(None)
```
This did **not** cause an error because it was called with `await agent.send_message_to_computer(...)`. Since `await` works with `Future` objects, the bug was not triggered. However, this is inconsistent and fragile; if the implementation ever changed to use `create_task`, it would break.

## 3. Solution

The solution is to use `unittest.mock.AsyncMock` for all mocked asynchronous methods. An `AsyncMock` object, when called, correctly returns a coroutine object that is compatible with both `await` and `asyncio.create_task`. This makes our tests more accurate, robust, and consistent.

## 4. Required Code Changes

We need to modify `dual_agent/tests/test_phone_agent.py` to use `AsyncMock` and add explanatory comments.

**File:** `dual_agent/tests/test_phone_agent.py`

```diff
# Near the top of the file, ensure AsyncMock is imported
- from unittest.mock import MagicMock, patch
+ from unittest.mock import MagicMock, patch, AsyncMock

# ... inside test_process_complete_speech test function ...

- # 替换发送消息函数，避免实际发送
- agent.send_message_to_computer = MagicMock()
- agent.send_message_to_computer.return_value = asyncio.Future()
- agent.send_message_to_computer.return_value.set_result(None)
+ # 使用AsyncMock确保mock的异步方法返回协程对象，提高代码一致性和健壮性
+ agent.send_message_to_computer = AsyncMock()


- # 替换speak函数，避免实际播放
- agent.speak = MagicMock()
- agent.speak.return_value = asyncio.Future()
- agent.speak.return_value.set_result(None)
+ # 使用AsyncMock确保mock的异步方法返回协程对象，以兼容asyncio.create_task()
+ agent.speak = AsyncMock()
```

## 5. Verification and Best Practices

1.  **Code Style:** With the changes above, all async methods are now mocked consistently using `AsyncMock`, which is a best practice.
2.  **Verification:** After applying the fix, run the complete test suite to ensure the fix is effective and has not introduced any regressions:
    ```sh
    pytest dual_agent/tests/test_phone_agent.py -v
    ```
This will confirm that all tests, including the previously failing one, now pass.

---

## Round 2: AttributeError with mock assertions

After fixing the initial `TypeError`, a new error appeared during the test run.

### 1. Bug and Symptoms (Round 2)

**Bug:** The test `test_process_complete_speech` still fails, but with a different error.

**Symptom:** When running `pytest`, the test now fails with an `AttributeError`:

```
AttributeError: Attributes cannot start with 'assert' or 'assret'
```

This error occurs on the line where we try to verify that the `think` method was called:
```python
# In dual_agent/tests/test_phone_agent.py
mock_engine.think.assert_awaited_once()
```

### 2. Root Cause Analysis (Round 2)

This error highlights a key difference between `MagicMock` and `AsyncMock`.

1.  **The Mock's Identity:** Our `mock_phone_agent` fixture uses `patch` to replace `MixedThinkingEngine`. By default, `patch` creates a `MagicMock` instance. Therefore, `mock_engine` is a `MagicMock`.
2.  **The Method's Identity:** When we access `mock_engine.think`, we are accessing a method on a `MagicMock`. This method is *also* a `MagicMock` by default.
3.  **The Wrong Tool for the Job:** The assertion method `assert_awaited_once()` is a special feature that **only exists on `AsyncMock` objects**. We are trying to call it on `mock_engine.think`, which is a `MagicMock`, not an `AsyncMock`.
4.  **The `AttributeError`:** `MagicMock` is designed to prevent developers from accidentally creating mock attributes that start with `assert` (e.g., `mock.assert_was_called = True`), as this could be confused with its built-in assertion methods (like `mock.assert_called_once()`). When our test tries to access `assert_awaited_once`, `MagicMock` sees the `assert` prefix and raises the `AttributeError` as a protective measure.

In short, we fixed the code under test to work with `await`, but we didn't update our test's *assertions* to use the correct async-aware mocking tools.

### 3. Solution (Round 2)

The correct and most robust solution is to ensure that **any mocked method that is asynchronous (`async def`) is replaced with an `AsyncMock` in our tests.**

This not only allows us to use the proper `assert_awaited_*` methods but also simplifies the test setup. Instead of manually creating and setting `Future` objects, we can just pass the return value directly to the `AsyncMock` constructor.

### 4. Required Code Changes (Round 2)

We need to refactor the test setup within `test_process_complete_speech` in the file `dual_agent/tests/test_phone_agent.py`.

```diff
# ... inside test_process_complete_speech test function ...

- # 模拟ASR结果
- mock_asr.process_audio_segment.return_value = asyncio.Future()
- mock_asr.process_audio_segment.return_value.set_result({"text": "这是测试语音", "segments": []})
+ # 将所有被await调用的mock方法替换为AsyncMock，以提供正确的返回类型和断言方法
+ mock_asr.process_audio_segment = AsyncMock(return_value={"text": "这是测试语音", "segments": []})
- 
-     # 模拟思考引擎结果
-     mock_engine.think.return_value = asyncio.Future()
-     mock_engine.think.return_value.set_result(("快速回复", "深度回复"))
+     mock_engine.think = AsyncMock(return_value=("快速回复", "深度回复"))
- 
-     # *** FIX: Configure generate_filler to be awaitable ***
-     mock_engine.generate_filler.return_value = asyncio.Future()
-     mock_engine.generate_filler.return_value.set_result("嗯，让我想想...")
+     mock_engine.generate_filler = AsyncMock(return_value="嗯，让我想想...")
- 
-     # 使用AsyncMock确保mock的异步方法返回协程对象，提高代码一致性和健壮性
-     agent.send_message_to_computer = AsyncMock()
+     agent.send_message_to_computer = AsyncMock()
- 
-     # 使用AsyncMock确保mock的异步方法返回协程对象，以兼容asyncio.create_task()
-     agent.speak = AsyncMock()
+     agent.speak = AsyncMock()
- 
-     # 模拟音频段
-     mock_audio = torch.zeros(16000)
+     mock_audio = torch.zeros(16000)
- 
-     # 执行测试
-     await agent.process_complete_speech(mock_audio)
+     await agent.process_complete_speech(mock_audio)
- 
-     # 验证ASR被调用
-     mock_asr.process_audio_segment.assert_called_once_with(mock_audio)
+     # 验证ASR被正确调用
+     mock_asr.process_audio_segment.assert_called_once_with(mock_audio)
- 
-     # 验证思考引擎被调用
-     mock_engine.think.assert_awaited_once()
+     # 验证思考引擎和填充语生成器被正确await
+     mock_engine.think.assert_awaited_once()
+     mock_engine.generate_filler.assert_awaited_once()
- 
-     # 验证消息已发送
-     agent.send_message_to_computer.assert_awaited_once()
+     # 验证消息已正确await发送
+     agent.send_message_to_computer.assert_awaited_once()
- 
-     # 验证speak被调用
-     # 第一次调用是填充语
-     # 第二次调用是深度回复
-     assert agent.speak.call_count == 2
-     agent.speak.assert_any_await("嗯，让我想想...")
-     agent.speak.assert_any_await("深度回复")
+     # 验证speak被调用两次（一次填充语，一次深度回复）
+     assert agent.speak.call_count == 2
+     agent.speak.assert_any_await("嗯，让我想想...")
+     agent.speak.assert_any_await("深度回复")

@pytest.mark.asyncio
async def test_process_complete_speech_no_filler(mock_phone_agent):
    """测试当已有快速回复时不生成填充语的情况"""
    agent, _, mock_asr, mock_engine, _ = mock_phone_agent

    # 设置已有快速回复，这将跳过填充语生成
    agent.last_fast_response = "之前的回复"

    # 配置Mocks
    mock_asr.process_audio_segment = AsyncMock(return_value={"text": "这是测试语音", "segments": []})
    mock_engine.think = AsyncMock(return_value=("快速回复", "深度回复"))
    mock_engine.generate_filler = AsyncMock(return_value="嗯，让我想想...")
    agent.send_message_to_computer = AsyncMock()
    agent.speak = AsyncMock()

    mock_audio = torch.zeros(16000)
    await agent.process_complete_speech(mock_audio)

    # 验证generate_filler没有被调用
    mock_engine.generate_filler.assert_not_awaited()

    # 验证speak只被调用一次（仅深度回复）
    agent.speak.assert_awaited_once_with("深度回复")

```
This final plan produces a much stronger, more reliable test suite. 